Workbook

Sheet Cover Sheet
A1: KEV Score Cards Review
B2: Facility Name: | C2: Brookfield
B3: Review Period: | C3: June 2025
B4: Date of Completion: | C4: 45835
B5: Audit Completed By: | C5: Amy Abraham, RN/ Lisa NortonRN
B7: Quality Area | C7: Total Possible Score | D7: Total Met Score | E7: Score
B8: Abuse & Grievances | C8: ='Abuse & Grievances'!E19 -> 50 | D8: ='Abuse & Grievances'!I19 -> 44 | E8: =D8/C8 -> 0.88
B9: Accidents & Incidents | C9: ='Accidents & Incidents'!E21 -> 60 | D9: ='Accidents & Incidents'!I21 -> 57 | E9: =D9/C9 -> 0.95
B10: Infection Prevention & Control | C10: ='Infection Prevention & Control'!E34 -> 130 | D10: ='Infection Prevention & Control'!I34 -> 107 | E10: =D10/C10 -> 0.82307692
B11: Skin Integrity & Wounds | C11: ='Skin Integrity & Wounds'!E35 -> 170 | D11: ='Skin Integrity & Wounds'!I35 -> 130 | E11: =D11/C11 -> 0.76470588
B12: Total Quality Review Score | C12: =SUM(C8:C11) -> 410 | D12: =SUM(D8:D11) -> 338 | E12: =D12/C12 -> 0.82439024
B13: Overall Score | C13: =E12 -> 0.82439024
A16: Note: This document is prepared for Quality Assurance and/or Peer Review and is privileged and confidential. It is protected from disclosure under both federal and state regulations related to Quality Assurance and Peer Review. This document is not to be shared, forwarded, disclosed or otherwise disseminated without explicit permission from the compliance department.
A17: Monthly Score Card Summary
A18: *Please copy and paste the % score from each category above into the cooresponding box below.
B19: Abuse & Grievances | C19: Accidents & Incidents | D19: Infection Prevention & Control | E19: Skin Integrity & Wounds | G19: Overall Score
A20: 45682
A21: 45713
A22: 45741
A23: 45772
A24: 45802
A25: 45833 | B25: 88 | C25: 95 | D25: 82.31 | E25: 76.47 | G25: 82.44
A26: 45863
A27: 45894
A28: 45925
A29: 45955
A30: 45986
A31: 46016

Sheet Abuse & Grievances
A1: Date: | G1: Reviewer: | H1: Lisa Norton
A4: Key Element Validation: Abuse & Grievances | E4: Resident Name: | F4: n/a | G4: n/a | H4: n/a
E5: Resident Selection: | F5: Select One: | G5: Select One: | H5: Select One:
E6: Abuse Type: | F6: Select One: | G6: Select One: | H6: Select One:
E7: Incident Description | F7: no abuse | G7: 6 grievances total
A8: Score Key: Met = 4 or 3 | Not Met = 0 | N/A | E8: Max Score | F8: Record Review Directions: Provide comments in "Comments" box and select most appropriate score using drop downs. If not applicable, select "N/A". | I8: Total Earned Score
A9: 1) Since your last review, have there been any grievances that met the potential for abuse? Were these reported to the clinical resource and the state as needed? Check the log for policy adherence and satisfaction with grievance resolutions. | E9: 10 | F9: 4 | G9: 3 | H9: 3 | I9: =IF(F9="N/A",4,F9)+IF(G9="N/A",3,G9)+IF(H9="N/A",3,H9) -> 10
A10: 1) Comments:
A11: 2) Review of the last months Resident Council Minutes, were all listings reported to the state that meet potiential criteria for abuse? | E11: 10 | F11: 10 | G11: N/A | H11: N/A | I11: =IF(F11="N/A",10,F11) -> 10
A12: 2) Comments:
A13: 3) After review of Risk Management Log, were all listings reported to the state that meet potiential criteria for abuse? Were applicable areas reviewed to include CPR codes, medication errors, fractures, head injuries, avoidable pressure areas, systemic/repeat patterns of care delivery failure (grooming, dehydration, MASD, malnourishment)? Was a determination made to validate, not validated, or leave as inconclusive? Review state reportables to ensure they followed policy. (Timely, thoroughness, resident protected appropriately, proper notifications, prevention, appropriate actions taken, etc) | E13: 10 | F13: 4 | G13: 3 | H13: 0 | I13: =IF(F13="N/A",4,F13)+IF(G13="N/A",3,G13)+IF(H13="N/A",3,H13) -> 7
A14: 3) Comments:
A15: 4) Observe to ensure narc counts done correctly and books are signed appropriately. Does the facility complete drug reconciliation reviews from pharmacy narcotic delivery notification? If issue identified, report to CEO and open investigation. | E15: 10 | F15: 4 | G15: 3 | H15: 0 | I15: =IF(F15="N/A",4,F15)+IF(G15="N/A",3,G15)+IF(H15="N/A",3,H15) -> 7
A16: 4) Comments:
A17: 5) Are abuse and significant events tracked and trended through QAPI? | E17: 10 | F17: 4 | G17: 3 | H17: 3 | I17: =IF(F17="N/A",4,F17)+IF(G17="N/A",3,G17)+IF(H17="N/A",3,H17) -> 10
A18: 5) Comments:
A19: Abuse & Grievances Total Possible Points: | E19: =E9+E11+E13+E15+E17 -> 50 | H19: Total Score: | I19: =SUM(I9:I18) -> 44
A21: ONLY PROCEED TO THIS SECTION IF SYSTEMS FOUND TO BE FAILING
D22: Employee Name: | I22: Is Follow-Up Needed? Yes/No
D23: Title:
A24: Staff Interviews: | E24: Directions: Interview three staff members, documenting answers and noting if follow-up education is needed.
A25: 1) Who is the facility abuse prevention coordinator? Who are mandatory reporters?
A26: 2) Who can be the perpetrator of abuse? What do you do if you hear of or see abuse?
A27: 3) List some signs of potentential abuse?
A28: 4) What is your role in the management of aggressive residents to include verbal altercations, bullying, intrusive wandering? Should you document potential behavioral conflicts where you intervened, and no negative outcome was immediately evident?
A29: 5) Use a case scenerio for abuse to determine if staff respond appropriately.

Sheet Accidents & Incidents
A1: Date: | G1: Reviewer: | H1: L. Norton
A4: Key Element Validation: Accidents & Incidents | E4: Resident Name:
E5: Resident Selection: | F5: Select One: | G5: Select One: | H5: Select One:
E6: Event Type: | F6: Select One: | G6: Select One: | H6: Select One:
E7: Incident Description
A8: Score Key: Met = 4 or 3 | Not Met = 0 | N/A | E8: Max Score | F8: Record Review Directions: Provide comments in "Comments" box and select most appropriate score using drop downs. If not applicable, select "N/A". | I8: Total Earned Score
A9: 1) Was event tracking managed? Were applicable areas reviewed to include immediate log of incident (WA/OR), entered into risk mgmt, reported if indicated, completed within 5 working days? | E9: 10 | F9: 4 | G9: 3 | H9: 0 | I9: =IF(F9="N/A",4,F9)+IF(G9="N/A",3,G9)+IF(H9="N/A",3,H9) -> 7
A10: 1) Comments:
A11: 2) Was risk anticipated? Was the care plan implemented prior to the incident? Were applicable areas reviewed to include MAHC-10 eval, smoking eval, wander risk, 48-hour care plan addresses risk and safety, type of supervision determined, plan is effective for BIMs score, behavioral impact is reviewed? | E11: 10 | F11: 4 | G11: 3 | H11: 3 | I11: =IF(F11="N/A",4,F11)+IF(G11="N/A",3,G11)+IF(H11="N/A",3,H11) -> 10
A12: 2) Comments:
A13: 3) Was policy followed post A/I occurance including but not limited to (if applicable): immediate assess/post fall eval, tx orders, applicable evals, alert charting, appropriate notifications, thorough clinical review, IDT review, thorough investigation, RCA, Care Plan update, appropriate referrals made, safety device audits as applicable, monitoring started and documented and review of conflicting data? | E13: 10 | F13: 4 | G13: 3 | H13: 3 | I13: =IF(F13="N/A",4,F13)+IF(G13="N/A",3,G13)+IF(H13="N/A",3,H13) -> 10
A14: 3) Comments:
A15: 4) Does weekly oversight committee show evidence of IDT review 1st business day post fall? Feasible RCA was used as the base for care plan updates? Referrals made as indicated? Review of fall risk report for new residents, residents w/change of condition, new falls, repeat falls for fall prevention plans/opportunities? | E15: 10 | F15: 4 | G15: 3 | H15: 3 | I15: =IF(F15="N/A",4,F15)+IF(G15="N/A",3,G15)+IF(H15="N/A",3,H15) -> 10
A16: 4) Comments:
A17: 5) Observe residents in the smoking area, as well as on the front sidewalk. Is a smoking eval current? Is there oxygen within 100 feet? Do residents hold their cigs/devices safely, extinquish properly, wear a safety apron if indicated, have burns in clothing? Where is smoking paraphenalia stored? Does the resident take items back to their room? | E17: 10 | F17: 4 | G17: 3 | H17: 3 | I17: =IF(F17="N/A",4,F17)+IF(G17="N/A",3,G17)+IF(H17="N/A",3,H17) -> 10
A18: 5) Comments:
A19: 6) For observed wandering/exit seeking residents, how do staff supervise/respond to a resident with exit seeking, rummaging, wandering behaviors? Are care plan interventions implemented consistently? Are they effective? Are elopment drills being performed as indicated? | E19: 10 | F19: N/A | G19: N/A | H19: N/A | I19: =IF(F19="N/A",4,F19)+IF(G19="N/A",3,G19)+IF(H19="N/A",3,H19) -> 10
A20: 6) Comments:
A21: Accidents & Incidents Total Possible Points: | E21: =E9+E11+E13+E15+E17+E19 -> 60 | H21: Total Score: | I21: =SUM(I9:I20) -> 57
A22: ONLY PROCEED TO THIS SECTION IF SYSTEMS FOUND TO BE FAILING
D23: Employee Name: | I23: Is Follow-Up Needed? Yes/No
D24: Title:
A25: Staff Interviews: | E25: Directions: Interview three staff members, documenting answers and noting if follow-up education is needed.
A26: 1) How do you know what interventions or assistance is needed for each resident?
A27: 2) How do you know if there are current changes to the plan of care?
A28: 3) What do you do if a resident refuses care or is a safety risk?
A29: 4) Is the resident involved in the development of their plan of care? Have you been included in the care plan development?
A30: 5) What are some risk factors for the resident?

Sheet Infection Prevention & Control
A1: Date: | B1: 45827 | G1: Reviewer: | H1: Amy Abraham/ Observation part- L. Norton
A4: Key Element Validation: Infection Prevention & Control | E4: Resident Name: | F4: Richard Markegard | G4: Urshell Robinette | H4: David Contreras
E5: Resident Selection: | F5: EBP | G5: Other | H5: Active Infection
E6: Precaution Type: | F6: EBP | G6: N/A | H6: Standard
E7: Item Description | F7: Chronic wounds | G7: General review | H7: Cellulitis with abo tx
A8: Score Key: Met = 4 or 3 | Not Met = 0 | N/A | E8: Max Score | F8: Record Review Directions: Provide comments in "Comments" box and select most appropriate score using drop downs. If not applicable, select "N/A". | I8: Total Earned Score
A9: 1) Are resident immunizations current and/or offered with evidence documented of risk and benefit education if refused? Were applicable areas reviewed to include influenza, pneumococcal, COVID-19, and others as indicated? | E9: 10 | F9: 4 | G9: 3 | H9: 3 | I9: =IF(F9="N/A",4,F9)+IF(G9="N/A",3,G9)+IF(H9="N/A",3,H9) -> 10
A10: 1) Comments:
A11: 2 ) Is resident TB testing completed on admission using the two-step method or evidence of chest xray has ruled out TB? | E11: 10 | F11: 4 | G11: 3 | H11: 3 | I11: =IF(F11="N/A",4,F11)+IF(G11="N/A",3,G11)+IF(H11="N/A",3,H11) -> 10
A12: 2) Comments: | F12: Annual TB screen due this month- did not see scheduled | G12: Did not see annual TB screen completed in last year. | H12: Did not see TB in the immunization tab. appears had CXR ordered but unable to locate CXR results.
A13: 3) Do residents with current infection/antibiotics meet McGeer's criteria? Were applicable areas reviewed to include corresponding orders, C&S, medication stop date, precautions, infection eval, resident advocate notification, resident education, care plan, alert charting monitor? Are infection surveillance obs audits done routinely and increased during outbreak and/or spread of infection? | E13: 10 | F13: 0 | G13: N/A | H13: 0 | I13: =IF(F13="N/A",4,F13)+IF(G13="N/A",3,G13)+IF(H13="N/A",3,H13) -> 3
A14: 3) Comments: | F14: Care plan not current for resolved PNA. EBP are not listed on orders or care plan for chronic open wounds. | H14: Cephaliexin for rt foot cellulitis- IP module is incomplete r/t infection details- if completed would do the tracking and trending. Does have infection eval done with the details.
A15: 4) Are current infections tracked and trended? Were applicable areas reviewed to include mapping, organisms, real time so that adjustments to care delivery can be addressed timely if indicated? | E15: 10 | F15: N/A | G15: N/A | H15: 0 | I15: =IF(F15="N/A",4,F15)+IF(G15="N/A",3,G15)+IF(H15="N/A",3,H15) -> 7
A16: 4) Comments: | F16: No active infection | G16: No active infection | H16: ABO time out is in process but was initiated 6/13. Review as of 6/19. Is currently listed in care plan as contact precautions r/t infection of foot but should also be on EBP for high contact activities.
A17: 5) Do respiratory care items have orders to change, cleanse, and store as indicated? Were applicable areas reviewed to include disposable items dated, concentrator filters cleaned, oxygen tubing changed/dated/stored, nebulizer changed/rinsedstored dry, CPAP/BiPAP/Vent change/cleanse/store, suction devices cleansed/disposed? | E17: 10 | F17: 4 | G17: 0 | H17: N/A | I17: =IF(F17="N/A",4,F17)+IF(G17="N/A",3,G17)+IF(H17="N/A",3,H17) -> 7
A18: 5) Comments: | F18: O2 order and prn neb order. Has not used neb tx in June- rec adding cleaning if uses or add to the prn order to clean when used. | G18: None ordered | H18: None ordered
A19: Score Key: Met = 10 | Not Met = 0 | N/A | E19: Max Score | F19: Observation Directions: Score the facility as a whole. If not applicable, select "N/A'. | I19: Total Earned Score
A20: 6) Are glucometers calibrated nightly if for multiple resident use or weekly if for single resident use devices? Are results documented multi-resident log/single-resident on TAR) and reviewed for adjustment if indicated? Are proper techniques used to clean the glucometers? | E20: 10 | F20: 10 | I20: =IF(F20="N/A",10,F20) -> 10
A21: 6) Comments:
A22: 7) Are refrigerators clean, with a thermometer, and monitored with documentation at least daily? Are temperatures appropriate for nourishment 33-40 degrees, medication 36-46 degrees, immunizations 36-46 degrees, lab draws 40-46 degrees? | E22: 10 | F22: 0 | I22: =IF(F22="N/A",10,F22) -> 0
A23: 7) Comments:
A24: 8) Do staff donn, doff, dispose PPE for EBP or TBP appropriately? Were applicable areas reviewed to include signage, supply quantity and storage, appropriate order, waste container inside the room, and a covered waste container outside the room door? | E24: 10 | F24: 10 | I24: =IF(F24="N/A",10,F24) -> 10
A25: 8) Comments:
A26: 9) Do staff perform hand hygiene appropriately and with frequency? Were applicable areas reviewed to include enter/exit of room, with glove use, during meals, for a full 20 seconds, clean towel to turn off water, rub ABHS until dry? Are residents assisted with hand hygiene after toileting, before meals, etc? | E26: 10 | F26: 10 | I26: =IF(F26="N/A",10,F26) -> 10
A27: 9) Comments:
A28: 10) If there is an outbreak, policies and procedures are followed? Were applicable areas reviewed to include source control, precautions, signage, PPE, notification, health dept engagement, medical director/QAPI sub-committee review? | E28: 10 | F28: 10 | I28: =IF(F28="N/A",10,F28) -> 10
A29: 10) Comments:
A30: 11) Do care givers complete peri care per guidelines? Were applicable areas reviewed to include glove changes, hand hygiene, no clean linen against the uniform, cleaning front to back/clean to dirty, no soiled linen on the floor, bagged linen disposal? | E30: 10 | F30: 10 | I30: =IF(F30="N/A",10,F30) -> 10
A31: 11) Comments:
A32: 12) Do LNs complete dressing changes, ointment application, respiratory tx, eye drops, injections, med pass with appropriate standard of practice infection control techniques? | E32: 10 | F32: 10 | I32: =IF(F32="N/A",10,F32) -> 10
A33: 12) Comments:
A34: Infection Prevention & Control Total Possible Points: | E34: =E9+E11+E13+E15+E17+E20+E22+E24+E26+E28+E30+E32+E36 -> 130 | H34: Total Score: | I34: =SUM(I9:I18)+SUM(I20:I33)+I36 -> 107
A35: ONLY PROCEED TO THIS SECTION IF SYSTEMS FOUND TO BE FAILING
A36: 13) Are laundry processing procedure appropriate for infection control? Were applicable areas reviewed to include glove/gown use with soiled items, cleansing the washer rim post loading/before closing the door, water temp/sanitizer process, hand hygiene, folding processed, delivery of linens in a covered cart? | E36: 10 | F36: N/A | I36: =IF(F36="N/A",10,F36) -> 10
A37: 13) Comments:
A38: ONLY PROCEED TO THIS SECTION IF SYSTEMS FOUND TO BE FAILING
D39: Employee Name: | I39: Is Follow-Up Needed? Yes/No
D40: Title:
A41: Staff Interviews: | E41: Directions: Interview three staff members, documenting answers and noting if follow-up education is needed.
A42: 1) When do you perform hand hygiene? What is the intended duration of the scrub/rub?
...

Sheet Skin Integrity & Wounds
A1: Date: | B1: 6/18/2025 - 6/19/25 | G1: Reviewer: | H1: Amy Abraham
A4: Key Element Validation: Skin Integrity & Wounds | E4: Resident Name: | F4: Richard Markegard | G4: Urshel Robinett | H4: David Contreras
E5: Resident Selection: | F5: Admit with Wound | G5: In-House Acquisition | H5: In-House Acquisition
E6: Wound Status | F6: Improving | G6: Improving | H6: New
E7: Item Description | F7: Has 11 active wounds in skin and wound | G7: Active wounds #5 IHA 2/23 and #6 IHA 4/13 | H7: wounds 1 and 2
A8: Score Key: Met = 4 or 3 | Not Met = 0 | N/A | E8: Max Score | F8: Record Review Directions: Briefly describe the wound and note the date of wound development, if relevant. If the question is not applicable, select "N/A". | I8: Total Earned Score
A9: 1) Was risk anticipated? Note Braden score. Was Braden completed timely on admission, quarterly, and as needed? Were care plan interventions established to address areas that trigger? Were applicable areas reviewed to include if indicated sensory, moisture, activity, mobility, nutrition, friction/shearing, hx, comorbidities? Please review H&P. Was risk anticipated? | E9: 10 | F9: 4 | G9: 3 | H9: 3 | I9: =IF(F9="N/A",4,F9)+IF(G9="N/A",3,G9)+IF(H9="N/A",3,H9) -> 10
A10: 1) Comments:
A11: 2) Were pressure reducing/relief devices implemented? Were applicable areas reviewed to include turn schedule, turning wedge/pillows, slip/turn sheet, toileting prog, air bed with setting, w/c cushion, heel pro/boots, supplements, geri-sleeves, derma-legs? | E11: 10 | F11: 4 | G11: 0 | H11: 3 | I11: =IF(F11="N/A",4,F11)+IF(G11="N/A",3,G11)+IF(H11="N/A",3,H11) -> 7
A12: 2) Comments: | G12: Rsd with devices/splints without skin checks prior to occurrence. braces to leg.. Was added post injury.
A13: 3) Weekly skin check scheduled and completed timely? Was skin health addressed reviewing for quality prevention plan? | E13: 10 | F13: 4 | G13: 3 | H13: 3 | I13: =IF(F13="N/A",4,F13)+IF(G13="N/A",3,G13)+IF(H13="N/A",3,H13) -> 10
A14: 3) Comments:
A15: 4) If new wound, was immediate assess/eval completed with photo/helix of significant wounds if indicated, incident completed in risk mgmt if in-house acquired, neglect verified/not verified/inconclusive? Was RCA Completed or identified? Is the RCA feasible? | E15: 10 | F15: N/A | G15: 0 | H15: 3 | I15: =IF(F15="N/A",4,F15)+IF(G15="N/A",3,G15)+IF(H15="N/A",3,H15) -> 7
A16: 4) Comments: | G16: Unable to verify RCA completed as not done in PCC. for the 2/23. The 4/13 for wound #6 indicates root cause although there is not a corresponding intervention listed. | H16: Identified 6/13- investigation in progress - due 6/20.
A17: 5) If new wound, was alert charting established with quality progress note x 72 hours for wounds/TAR notation x 7 days for bruises to address potential latent injury, response to treatment, effectiveness of care plan updates? | E17: 10 | F17: N/A | G17: 3 | H17: 3 | I17: =IF(F17="N/A",4,F17)+IF(G17="N/A",3,G17)+IF(H17="N/A",3,H17) -> 10
A18: 5) Comments:
A19: 6) Is treatment order complete? Were applicable areas reviewed to include site, type, cleanse with, apply, cover with, frequency? If under a brace is a daily skin monitor on TAR? Is an airbed in use with setting monitor on MAR? | E19: 10 | F19: 0 | G19: 0 | H19: 3 | I19: =IF(F19="N/A",4,F19)+IF(G19="N/A",3,G19)+IF(H19="N/A",3,H19) -> 3
A20: 6) Comments: | F20: Treatment order 6/13/25 does not match order given r/t collegen | G20: Need to clarify if leg wounds are still lactive- last eval was in April. Close out if no longer present.
A21: 7) Is the TAR consistenly completed for wound treatment plan? Are changes in orders implemented timely? | E21: 10 | F21: 4 | G21: 3 | H21: 3 | I21: =IF(F21="N/A",4,F21)+IF(G21="N/A",3,G21)+IF(H21="N/A",3,H21) -> 10
A22: 7) Comments: | G22: For toe bruise
A23: 8) Is current wound eval and photo completed weekly and locked timely? Is PUSH score address if indicated? If wound is not improving every 14 days is adv practice practioner notified with follow-up and new orders and care plan evident? | E23: 10 | F23: 0 | G23: 0 | H23: 0 | I23: =IF(F23="N/A",4,F23)+IF(G23="N/A",3,G23)+IF(H23="N/A",3,H23) -> 0
A24: 8) Comments: | G24: Wound #5 is a bruise from trauma. Typically, would monitor this on the treatment record til resolved versus skin and wound. Recommend reviewing process of what wounds monitor in skin and wound and which type will track on TAR. Attached an example that could be reviewed /updated to facility preference. wound #6 was last evaluated in April. Is this still an active wound? There is not an active order for this. If area is resolved, then would resolve the wound. | H24: wound eval done on new PI right foot but is not comprehensive. there is also an active wound of the scrotum from April that if resolved should close out.
A25: 9) Is the resident and/or resident representative aware of current wound status? | E25: 10 | F25: N/A | G25: 3 | H25: 3 | I25: =IF(F25="N/A",4,F25)+IF(G25="N/A",3,G25)+IF(H25="N/A",3,H25) -> 10
A26: 9) Comments: | G26: Yes for both
A27: 10) Was physician notified of new wound or change in wound status? | E27: 10 | F27: N/A | G27: 3 | H27: 3 | I27: =IF(F27="N/A",4,F27)+IF(G27="N/A",3,G27)+IF(H27="N/A",3,H27) -> 10
A28: 10) Comments: | G28: Yes for both
A29: 11) Does the current RD note reflect wound risk or management of increased nutritional needs, labs? | E29: 10 | F29: 4 | G29: N/A | H29: N/A | I29: =IF(F29="N/A",4,F29)+IF(G29="N/A",3,G29)+IF(H29="N/A",3,H29) -> 10
A30: 11) Comments: | G30: wound #5 is a bruise and #6 is to be verified as last reviewed in April. No current tx. last NAR was in March. Due this month. | H30: Occurred 6/13- verify referred
A31: 12) Was the care plan established for risk, prevention, and actual wound site resolution? Was Monitoring established as applicable? Was plan for implementation observed, documented and reassessed as necessary? | E31: 10 | F31: 0 | G31: 0 | H31: 3 | I31: =IF(F31="N/A",4,F31)+IF(G31="N/A",3,G31)+IF(H31="N/A",3,H31) -> 3
A32: 12) Comments: | G32: skin care plan to be reviewed and updated for current skin issues and interventions. Has historical information listed still active. | H32: Care plan will need reviewed and updated which is pending with open risk management. To be closed 6/20.
A33: 13) Does weekly oversight committee show evidence of wound documentation review to include third-party notes, resident non-compliance, new wounds RCA, change of condition residents newly at risk, follow-up notification to practitioner and resident advocate, evident of IDT involvement? | E33: 10 | F33: 0 | G33: 0 | H33: 0 | I33: =IF(F33="N/A",4,F33)+IF(G33="N/A",3,G33)+IF(H33="N/A",3,H33) -> 0
A34: 13) Comments: | F34: Do not see evidence of this process | G34: Did not see evidence of this process | H34: Did not see evidence of this process
A35: Skin Integirty & Wounds Total Possible Score: | E35: =E9+E11+E13+E15+E17+E19+E21+E23+E25+E27+E29+E31+E33+E38+E40+E42+E44 -> 170 | H35: Total Score: | I35: =SUM(I9:I34)+SUM(I38:I45) -> 130
A36: ONLY PROCEED TO THIS SECTION IF SYSTEMS FOUND TO BE FAILING
A37: Score Key: Met = 10 | Not Met = 0 | N/A | E37: Max Score | F37: Observation Directions: Score the facility as a whole. If not applicable, select "N/A". | I37: Total Earned Score
A38: Was dressing removed intact, dated, initialed, supplies as ordered? Does the wound look infected? Was treatment completed per prescriber's order and with acceptable clinical standards of practice to include EBP, hand hygiene, glove use, gown use, if multiple wounds the most contaminated ulcer treated last? Did resident show evidence of pain? Was it addressed? | E38: 10 | F38: N/A | I38: =IF(F38="N/A",10,F38) -> 10
A39: Comments:
A40: Clean wound dressing supplies are handled to prevent cross-contamination? Were applicable areas reviewed to include treatment cart remains outside res room, unused supplies taken into room are discarded/stored under clean conditions in room, creams/ointments are dedicated to a single res? | E40: 10 | F40: N/A | I40: =IF(F40="N/A",10,F40) -> 10
A41: Comments:
A42: Is the resident turned/repositioned timely, pressure is avoided on actual wound sites, pressure relief devices positioned/set appropriately? | E42: 10 | F42: N/A | I42: =IF(F42="N/A",10,F42) -> 10
...

Sheet Data
A1: A&I Safety Events | C1: A&I Resident Selection | E1: 1st Score Column | G1: 2nd & 3rd Score Column | I1: Observations | K1: Follow-Up Needed?
A2: Select One: | C2: Select One:
A3: Fall | C3: Admit Last 30 Days | E3: 4 | G3: 3 | I3: 10 | K3: Yes
A4: Near Miss | C4: Change of Condition | E4: 0 | G4: 0 | I4: 0 | K4: No
A5: Other | C5: ER Visit | E5: N/A | G5: N/A | I5: N/A
A6: Resident Altercation | C6: Fall | K6: Facility Name
A7: Safety/Entrapment | C7: Medication Error | I7: Review Period
A8: Smoking | C8: Repeat Fall | K8: Alderwood Park
A9: Wander/Elopement | C9: Reportable | I9: January 2025 | K9: Arbor Valley
I10: February 2025 | K10: Aspen Park
E11: Discharge/Transfer Location | G11: Discharge/Transfer Event Type | I11: March 2025 | K11: Boswell Transitional
A12: Wound Status | C12: Skin Resident Selection | E12: Select One: | G12: Select One: | I12: April 2025 | K12: Brookfield
A13: Select One: | C13: Select One: | E13: ALF | G13: Death | I13: May 2025 | K13: Caldwell Care
A14: Deteriorating | C14: Admit with Wound | E14: Home | G14: Emergent Transfer | I14: June 2025 | K14: Canyon West
A15: Healed | C15: In-House Acquisition | E15: Hospital | G15: Planned Discharge | I15: July 2025 | K15: Cascadia of Boise
A16: Improving | C16: New Admit | E16: Mortuary | I16: August 2025 | K16: Cascadia of Lewiston
A17: New | C17: Non-Pressure | E17: Other | G17: IP Precaution Type | I17: September 2025 | K17: Cascadia of Nampa
A18: No Current Wound | E18: Retirement | G18: Select One: | I18: October 2025 | K18: Cherry Ridge
A19: Stable | C19: Abuse Event Type | E19: SNF | G19: EBP | I19: November 2025 | K19: Clarkston
A20: Stalled | C20: Select One: | G20: Prevention | I20: December 2025 | K20: Clearwater
C21: Exploitation | E21: IP Resident Selection | G21: Standard | K21: Coeur d'Alene
A22: Abuse Resident Selection | C22: Mental | E22: Select One: | G22: TBP | K22: Colfax
A23: Select One: | C23: Misappropriation | E23: Active Infection | G23: N/A | K23: Colville
A24: Grievances | C24: Neglect | E24: Colonized | K24: Creekside
A25: Other | C25: Physical | E25: EBP | K25: Curry Village (ALF)
A26: Progress Note | C26: Res-to-Res | E26: New Admission | K26: Curry Village (SNF)
A27: Risk Management | C27: Sexual | E27: TBP | K27: Eagle Rock
A28: Abaqis Interviews | C28: Verbal | E28: Vent/Trach | K28: Fairlawn
C29: Other | E29: Other | K29: Grangeville
K30: Highland
K31: Hudson Bay
K32: Lewiston Transitional
K33: Libby Care Center
K34: Mount Ascension Transitional
K35: Mountain Valley
K36: Mountain View
K37: NorthPark
K38: Paradise Creek
K39: Payette
K40: Royal Plaza
...
